import { useState, useEffect, useCallback } from "react";
import { AuthState, LoginCredentials, SignupCredentials } from "../types/auth";
import { authService } from "../services/auth";
export const useAuth = () => {
  const [state, setState] = useState<AuthState>({
    user: null,
    isAuthenticated: false,
    isLoading: true,
    error: null,
  });

  // Check for existing session on mount
  useEffect(() => {
    const user = authService.getCurrentUser();
    setState({
      user,
      isAuthenticated: !!user,
      isLoading: false,
      error: null,
    });
  }, []);

  const login = useCallback(async (credentials: LoginCredentials) => {
    setState((prev) => ({ ...prev, isLoading: true, error: null }));

    try {
      const response = await authService.login(credentials);

      if (response.success && response.user) {
        setState({
          user: response.user,
          isAuthenticated: true,
          isLoading: false,
          error: null,
        });
        return { success: true };
      } else {
        setState((prev) => ({
          ...prev,
          isLoading: false,
          error: response.message || "Login failed",
        }));
        return { success: false, error: response.message };
      }
    } catch (error) {
      const errorMessage = "An unexpected error occurred";
      setState((prev) => ({
        ...prev,
        isLoading: false,
        error: errorMessage,
      }));
      return { success: false, error: errorMessage };
    }
  }, []);

  const signup = useCallback(async (credentials: SignupCredentials) => {
    setState((prev) => ({ ...prev, isLoading: true, error: null }));

    try {
      const response = await authService.signup(credentials);

      if (response.success && response.user) {
        setState({
          user: response.user,
          isAuthenticated: true,
          isLoading: false,
          error: null,
        });
        return { success: true };
      } else {
        setState((prev) => ({
          ...prev,
          isLoading: false,
          error: response.message || "Signup failed",
        }));
        return { success: false, error: response.message };
      }
    } catch (error) {
      const errorMessage = "An unexpected error occurred";
      setState((prev) => ({
        ...prev,
        isLoading: false,
        error: errorMessage,
      }));
      return { success: false, error: errorMessage };
    }
  }, []);

  const logout = useCallback(async () => {
    setState((prev) => ({ ...prev, isLoading: true }));

    try {
      await authService.logout();
      setState({
        user: null,
        isAuthenticated: false,
        isLoading: false,
        error: null,
      });
    } catch (error) {
      setState({
        user: null,
        isAuthenticated: false,
        isLoading: false,
        error: null,
      });
    }
  }, []);

  const clearError = useCallback(() => {
    setState((prev) => ({ ...prev, error: null }));
  }, []);

  return {
    ...state,
    login,
    signup,
    logout,
    clearError,
  };
};
